[2025-03-18T13:40:01.574+0000] {local_task_job_runner.py:123} INFO - ::group::Pre task execution logs
[2025-03-18T13:40:01.582+0000] {taskinstance.py:2614} INFO - Dependencies all met for dep_context=non-requeueable deps ti=<TaskInstance: sevdesk_to_hubspot_sync_dynamic.detect_new_contact_in_sevdesk scheduled__2025-03-18T13:35:00+00:00 [queued]>
[2025-03-18T13:40:01.585+0000] {taskinstance.py:2614} INFO - Dependencies all met for dep_context=requeueable deps ti=<TaskInstance: sevdesk_to_hubspot_sync_dynamic.detect_new_contact_in_sevdesk scheduled__2025-03-18T13:35:00+00:00 [queued]>
[2025-03-18T13:40:01.586+0000] {taskinstance.py:2867} INFO - Starting attempt 1 of 2
[2025-03-18T13:40:01.592+0000] {taskinstance.py:2890} INFO - Executing <Task(SevDeskNewContactSensor): detect_new_contact_in_sevdesk> on 2025-03-18 13:35:00+00:00
[2025-03-18T13:40:01.596+0000] {warnings.py:112} WARNING - /home/***/.local/lib/python3.12/site-packages/***/task/task_runner/standard_task_runner.py:70: DeprecationWarning: This process (pid=5315) is multi-threaded, use of fork() may lead to deadlocks in the child.
  pid = os.fork()

[2025-03-18T13:40:01.597+0000] {standard_task_runner.py:72} INFO - Started process 5316 to run task
[2025-03-18T13:40:01.597+0000] {standard_task_runner.py:104} INFO - Running: ['***', 'tasks', 'run', 'sevdesk_to_hubspot_sync_dynamic', 'detect_new_contact_in_sevdesk', 'scheduled__2025-03-18T13:35:00+00:00', '--job-id', '280', '--raw', '--subdir', 'DAGS_FOLDER/dynamicsensor_dag.py', '--cfg-path', '/tmp/tmpgcy_52ea']
[2025-03-18T13:40:01.598+0000] {standard_task_runner.py:105} INFO - Job 280: Subtask detect_new_contact_in_sevdesk
[2025-03-18T13:40:01.790+0000] {task_command.py:467} INFO - Running <TaskInstance: sevdesk_to_hubspot_sync_dynamic.detect_new_contact_in_sevdesk scheduled__2025-03-18T13:35:00+00:00 [running]> on host 9c697b397d93
[2025-03-18T13:40:01.823+0000] {taskinstance.py:3134} INFO - Exporting env vars: AIRFLOW_CTX_DAG_OWNER='***' AIRFLOW_CTX_DAG_ID='sevdesk_to_hubspot_sync_dynamic' AIRFLOW_CTX_TASK_ID='detect_new_contact_in_sevdesk' AIRFLOW_CTX_EXECUTION_DATE='2025-03-18T13:35:00+00:00' AIRFLOW_CTX_TRY_NUMBER='1' AIRFLOW_CTX_DAG_RUN_ID='scheduled__2025-03-18T13:35:00+00:00'
[2025-03-18T13:40:01.824+0000] {logging_mixin.py:190} INFO - Task instance is in running state
[2025-03-18T13:40:01.824+0000] {logging_mixin.py:190} INFO -  Previous state of the Task instance: queued
[2025-03-18T13:40:01.824+0000] {logging_mixin.py:190} INFO - Current task name:detect_new_contact_in_sevdesk state:running start_date:2025-03-18 13:40:01.582982+00:00
[2025-03-18T13:40:01.824+0000] {logging_mixin.py:190} INFO - Dag name:sevdesk_to_hubspot_sync_dynamic and current dag run status:running
[2025-03-18T13:40:01.824+0000] {taskinstance.py:732} INFO - ::endgroup::
[2025-03-18T13:40:02.041+0000] {logging_mixin.py:190} INFO - No new contact found yet.
[2025-03-18T13:41:02.232+0000] {logging_mixin.py:190} INFO - No new contact found yet.
[2025-03-18T13:42:02.442+0000] {logging_mixin.py:190} INFO - No new contact found yet.
[2025-03-18T13:43:02.677+0000] {logging_mixin.py:190} INFO - No new contact found yet.
[2025-03-18T13:44:02.903+0000] {logging_mixin.py:190} INFO - No new contact found yet.
[2025-03-18T13:45:03.092+0000] {logging_mixin.py:190} INFO - No new contact found yet.
[2025-03-18T13:46:03.361+0000] {logging_mixin.py:190} INFO - No new contact found yet.
[2025-03-18T13:47:03.582+0000] {logging_mixin.py:190} INFO - No new contact found yet.
[2025-03-18T13:48:03.774+0000] {logging_mixin.py:190} INFO - No new contact found yet.
[2025-03-18T13:49:03.996+0000] {logging_mixin.py:190} INFO - No new contact found yet.
[2025-03-18T13:50:04.190+0000] {logging_mixin.py:190} INFO - No new contact found yet.
[2025-03-18T13:50:04.193+0000] {taskinstance.py:3313} ERROR - Task failed with exception
Traceback (most recent call last):
  File "/home/airflow/.local/lib/python3.12/site-packages/airflow/models/taskinstance.py", line 768, in _execute_task
    result = _execute_callable(context=context, **execute_callable_kwargs)
             ^^^^^^^^^^^^^^^^^^^^^^^^^^^^^^^^^^^^^^^^^^^^^^^^^^^^^^^^^^^^^
  File "/home/airflow/.local/lib/python3.12/site-packages/airflow/models/taskinstance.py", line 734, in _execute_callable
    return ExecutionCallableRunner(
           ^^^^^^^^^^^^^^^^^^^^^^^^
  File "/home/airflow/.local/lib/python3.12/site-packages/airflow/utils/operator_helpers.py", line 252, in run
    return self.func(*args, **kwargs)
           ^^^^^^^^^^^^^^^^^^^^^^^^^^
  File "/home/airflow/.local/lib/python3.12/site-packages/airflow/models/baseoperator.py", line 424, in wrapper
    return func(self, *args, **kwargs)
           ^^^^^^^^^^^^^^^^^^^^^^^^^^^
  File "/home/airflow/.local/lib/python3.12/site-packages/airflow/sensors/base.py", line 326, in execute
    raise AirflowSensorTimeout(message)
airflow.exceptions.AirflowSensorTimeout: Sensor has timed out; run duration of 602.3716791490006 seconds exceeds the specified timeout of 600.0.
[2025-03-18T13:50:04.210+0000] {logging_mixin.py:190} INFO - Task instance in failure state
[2025-03-18T13:50:04.210+0000] {logging_mixin.py:190} INFO - Task start:2025-03-18 13:40:01.582982+00:00 end:2025-03-18 13:50:04.209287+00:00 duration:602.626305
[2025-03-18T13:50:04.211+0000] {logging_mixin.py:190} INFO - Task:<Task(SevDeskNewContactSensor): detect_new_contact_in_sevdesk> dag:<DAG: sevdesk_to_hubspot_sync_dynamic> dagrun:<DagRun sevdesk_to_hubspot_sync_dynamic @ 2025-03-18 13:35:00+00:00: scheduled__2025-03-18T13:35:00+00:00, state:running, queued_at: 2025-03-18 13:40:00.846966+00:00. externally triggered: False>
[2025-03-18T13:50:04.211+0000] {logging_mixin.py:190} INFO - Failure caused by Sensor has timed out; run duration of 602.3716791490006 seconds exceeds the specified timeout of 600.0.
[2025-03-18T13:50:04.211+0000] {taskinstance.py:1226} INFO - Immediate failure requested. Marking task as FAILED. dag_id=sevdesk_to_hubspot_sync_dynamic, task_id=detect_new_contact_in_sevdesk, run_id=scheduled__2025-03-18T13:35:00+00:00, execution_date=20250318T133500, start_date=20250318T134001, end_date=20250318T135004
[2025-03-18T13:50:04.229+0000] {taskinstance.py:341} INFO - ::group::Post task execution logs
[2025-03-18T13:50:04.230+0000] {standard_task_runner.py:124} ERROR - Failed to execute job 280 for task detect_new_contact_in_sevdesk (Sensor has timed out; run duration of 602.3716791490006 seconds exceeds the specified timeout of 600.0.; 5316)
Traceback (most recent call last):
  File "/home/airflow/.local/lib/python3.12/site-packages/airflow/task/task_runner/standard_task_runner.py", line 117, in _start_by_fork
    ret = args.func(args, dag=self.dag)
          ^^^^^^^^^^^^^^^^^^^^^^^^^^^^^
  File "/home/airflow/.local/lib/python3.12/site-packages/airflow/cli/cli_config.py", line 49, in command
    return func(*args, **kwargs)
           ^^^^^^^^^^^^^^^^^^^^^
  File "/home/airflow/.local/lib/python3.12/site-packages/airflow/utils/cli.py", line 116, in wrapper
    return f(*args, **kwargs)
           ^^^^^^^^^^^^^^^^^^
  File "/home/airflow/.local/lib/python3.12/site-packages/airflow/cli/commands/task_command.py", line 483, in task_run
    task_return_code = _run_task_by_selected_method(args, _dag, ti)
                       ^^^^^^^^^^^^^^^^^^^^^^^^^^^^^^^^^^^^^^^^^^^^
  File "/home/airflow/.local/lib/python3.12/site-packages/airflow/cli/commands/task_command.py", line 256, in _run_task_by_selected_method
    return _run_raw_task(args, ti)
           ^^^^^^^^^^^^^^^^^^^^^^^
  File "/home/airflow/.local/lib/python3.12/site-packages/airflow/cli/commands/task_command.py", line 341, in _run_raw_task
    return ti._run_raw_task(
           ^^^^^^^^^^^^^^^^^
  File "/home/airflow/.local/lib/python3.12/site-packages/airflow/utils/session.py", line 97, in wrapper
    return func(*args, session=session, **kwargs)
           ^^^^^^^^^^^^^^^^^^^^^^^^^^^^^^^^^^^^^^
  File "/home/airflow/.local/lib/python3.12/site-packages/airflow/models/taskinstance.py", line 3006, in _run_raw_task
    return _run_raw_task(
           ^^^^^^^^^^^^^^
  File "/home/airflow/.local/lib/python3.12/site-packages/airflow/models/taskinstance.py", line 274, in _run_raw_task
    TaskInstance._execute_task_with_callbacks(
  File "/home/airflow/.local/lib/python3.12/site-packages/airflow/models/taskinstance.py", line 3161, in _execute_task_with_callbacks
    result = self._execute_task(context, task_orig)
             ^^^^^^^^^^^^^^^^^^^^^^^^^^^^^^^^^^^^^^
  File "/home/airflow/.local/lib/python3.12/site-packages/airflow/models/taskinstance.py", line 3185, in _execute_task
    return _execute_task(self, context, task_orig)
           ^^^^^^^^^^^^^^^^^^^^^^^^^^^^^^^^^^^^^^^
  File "/home/airflow/.local/lib/python3.12/site-packages/airflow/models/taskinstance.py", line 768, in _execute_task
    result = _execute_callable(context=context, **execute_callable_kwargs)
             ^^^^^^^^^^^^^^^^^^^^^^^^^^^^^^^^^^^^^^^^^^^^^^^^^^^^^^^^^^^^^
  File "/home/airflow/.local/lib/python3.12/site-packages/airflow/models/taskinstance.py", line 734, in _execute_callable
    return ExecutionCallableRunner(
           ^^^^^^^^^^^^^^^^^^^^^^^^
  File "/home/airflow/.local/lib/python3.12/site-packages/airflow/utils/operator_helpers.py", line 252, in run
    return self.func(*args, **kwargs)
           ^^^^^^^^^^^^^^^^^^^^^^^^^^
  File "/home/airflow/.local/lib/python3.12/site-packages/airflow/models/baseoperator.py", line 424, in wrapper
    return func(self, *args, **kwargs)
           ^^^^^^^^^^^^^^^^^^^^^^^^^^^
  File "/home/airflow/.local/lib/python3.12/site-packages/airflow/sensors/base.py", line 326, in execute
    raise AirflowSensorTimeout(message)
airflow.exceptions.AirflowSensorTimeout: Sensor has timed out; run duration of 602.3716791490006 seconds exceeds the specified timeout of 600.0.
[2025-03-18T13:50:04.266+0000] {local_task_job_runner.py:266} INFO - Task exited with return code 1
[2025-03-18T13:50:04.284+0000] {taskinstance.py:3901} INFO - 0 downstream tasks scheduled from follow-on schedule check
[2025-03-18T13:50:04.286+0000] {local_task_job_runner.py:245} INFO - ::endgroup::
