[2025-03-17T16:39:56.727+0000] {local_task_job_runner.py:123} INFO - ::group::Pre task execution logs
[2025-03-17T16:39:56.733+0000] {taskinstance.py:2614} INFO - Dependencies all met for dep_context=non-requeueable deps ti=<TaskInstance: sevdesk_to_hubspot.create_contact_in_hubspot manual__2025-03-17T16:34:49.936648+00:00 [queued]>
[2025-03-17T16:39:56.736+0000] {taskinstance.py:2614} INFO - Dependencies all met for dep_context=requeueable deps ti=<TaskInstance: sevdesk_to_hubspot.create_contact_in_hubspot manual__2025-03-17T16:34:49.936648+00:00 [queued]>
[2025-03-17T16:39:56.736+0000] {taskinstance.py:2867} INFO - Starting attempt 2 of 2
[2025-03-17T16:39:56.804+0000] {taskinstance.py:2890} INFO - Executing <Task(PythonOperator): create_contact_in_hubspot> on 2025-03-17 16:34:49.936648+00:00
[2025-03-17T16:39:56.807+0000] {warnings.py:112} WARNING - /home/***/.local/lib/python3.12/site-packages/***/task/task_runner/standard_task_runner.py:70: DeprecationWarning: This process (pid=496) is multi-threaded, use of fork() may lead to deadlocks in the child.
  pid = os.fork()

[2025-03-17T16:39:56.807+0000] {standard_task_runner.py:72} INFO - Started process 497 to run task
[2025-03-17T16:39:56.808+0000] {standard_task_runner.py:104} INFO - Running: ['***', 'tasks', 'run', 'sevdesk_to_hubspot', 'create_contact_in_hubspot', 'manual__2025-03-17T16:34:49.936648+00:00', '--job-id', '11', '--raw', '--subdir', 'DAGS_FOLDER/sevdesk_to_hubspot.py', '--cfg-path', '/tmp/tmp5zk_b6pk']
[2025-03-17T16:39:56.808+0000] {standard_task_runner.py:105} INFO - Job 11: Subtask create_contact_in_hubspot
[2025-03-17T16:39:56.832+0000] {task_command.py:467} INFO - Running <TaskInstance: sevdesk_to_hubspot.create_contact_in_hubspot manual__2025-03-17T16:34:49.936648+00:00 [running]> on host 07f4f36f3e31
[2025-03-17T16:39:56.857+0000] {taskinstance.py:3134} INFO - Exporting env vars: AIRFLOW_CTX_DAG_OWNER='***' AIRFLOW_CTX_DAG_ID='sevdesk_to_hubspot' AIRFLOW_CTX_TASK_ID='create_contact_in_hubspot' AIRFLOW_CTX_EXECUTION_DATE='2025-03-17T16:34:49.936648+00:00' AIRFLOW_CTX_TRY_NUMBER='2' AIRFLOW_CTX_DAG_RUN_ID='manual__2025-03-17T16:34:49.936648+00:00'
[2025-03-17T16:39:56.857+0000] {logging_mixin.py:190} INFO - Task instance is in running state
[2025-03-17T16:39:56.857+0000] {logging_mixin.py:190} INFO -  Previous state of the Task instance: queued
[2025-03-17T16:39:56.857+0000] {logging_mixin.py:190} INFO - Current task name:create_contact_in_hubspot state:running start_date:2025-03-17 16:39:56.734158+00:00
[2025-03-17T16:39:56.858+0000] {logging_mixin.py:190} INFO - Dag name:sevdesk_to_hubspot and current dag run status:running
[2025-03-17T16:39:56.858+0000] {taskinstance.py:732} INFO - ::endgroup::
[2025-03-17T16:39:57.377+0000] {taskinstance.py:3313} ERROR - Task failed with exception
Traceback (most recent call last):
  File "/home/airflow/.local/lib/python3.12/site-packages/airflow/models/taskinstance.py", line 768, in _execute_task
    result = _execute_callable(context=context, **execute_callable_kwargs)
             ^^^^^^^^^^^^^^^^^^^^^^^^^^^^^^^^^^^^^^^^^^^^^^^^^^^^^^^^^^^^^
  File "/home/airflow/.local/lib/python3.12/site-packages/airflow/models/taskinstance.py", line 734, in _execute_callable
    return ExecutionCallableRunner(
           ^^^^^^^^^^^^^^^^^^^^^^^^
  File "/home/airflow/.local/lib/python3.12/site-packages/airflow/utils/operator_helpers.py", line 252, in run
    return self.func(*args, **kwargs)
           ^^^^^^^^^^^^^^^^^^^^^^^^^^
  File "/home/airflow/.local/lib/python3.12/site-packages/airflow/models/baseoperator.py", line 424, in wrapper
    return func(self, *args, **kwargs)
           ^^^^^^^^^^^^^^^^^^^^^^^^^^^
  File "/home/airflow/.local/lib/python3.12/site-packages/airflow/operators/python.py", line 238, in execute
    return_value = self.execute_callable()
                   ^^^^^^^^^^^^^^^^^^^^^^^
  File "/home/airflow/.local/lib/python3.12/site-packages/airflow/operators/python.py", line 256, in execute_callable
    return runner.run(*self.op_args, **self.op_kwargs)
           ^^^^^^^^^^^^^^^^^^^^^^^^^^^^^^^^^^^^^^^^^^^
  File "/home/airflow/.local/lib/python3.12/site-packages/airflow/utils/operator_helpers.py", line 252, in run
    return self.func(*args, **kwargs)
           ^^^^^^^^^^^^^^^^^^^^^^^^^^
  File "/opt/airflow/dags/sevdesk_to_hubspot.py", line 106, in create_contact_in_hubspot
    raise ValueError(f"Failed to create contact in HubSpot. Status Code: {create_response.status_code}")
ValueError: Failed to create contact in HubSpot. Status Code: 409
[2025-03-17T16:39:57.390+0000] {logging_mixin.py:190} INFO - Task instance in failure state
[2025-03-17T16:39:57.391+0000] {logging_mixin.py:190} INFO - Task start:2025-03-17 16:39:56.734158+00:00 end:2025-03-17 16:39:57.389898+00:00 duration:0.65574
[2025-03-17T16:39:57.391+0000] {logging_mixin.py:190} INFO - Task:<Task(PythonOperator): create_contact_in_hubspot> dag:<DAG: sevdesk_to_hubspot> dagrun:<DagRun sevdesk_to_hubspot @ 2025-03-17 16:34:49.936648+00:00: manual__2025-03-17T16:34:49.936648+00:00, state:running, queued_at: 2025-03-17 16:34:49.954204+00:00. externally triggered: True>
[2025-03-17T16:39:57.391+0000] {logging_mixin.py:190} INFO - Failure caused by Failed to create contact in HubSpot. Status Code: 409
[2025-03-17T16:39:57.392+0000] {taskinstance.py:1226} INFO - Marking task as FAILED. dag_id=sevdesk_to_hubspot, task_id=create_contact_in_hubspot, run_id=manual__2025-03-17T16:34:49.936648+00:00, execution_date=20250317T163449, start_date=20250317T163956, end_date=20250317T163957
[2025-03-17T16:39:57.411+0000] {taskinstance.py:341} INFO - ::group::Post task execution logs
[2025-03-17T16:39:57.411+0000] {standard_task_runner.py:124} ERROR - Failed to execute job 11 for task create_contact_in_hubspot (Failed to create contact in HubSpot. Status Code: 409; 497)
Traceback (most recent call last):
  File "/home/airflow/.local/lib/python3.12/site-packages/airflow/task/task_runner/standard_task_runner.py", line 117, in _start_by_fork
    ret = args.func(args, dag=self.dag)
          ^^^^^^^^^^^^^^^^^^^^^^^^^^^^^
  File "/home/airflow/.local/lib/python3.12/site-packages/airflow/cli/cli_config.py", line 49, in command
    return func(*args, **kwargs)
           ^^^^^^^^^^^^^^^^^^^^^
  File "/home/airflow/.local/lib/python3.12/site-packages/airflow/utils/cli.py", line 116, in wrapper
    return f(*args, **kwargs)
           ^^^^^^^^^^^^^^^^^^
  File "/home/airflow/.local/lib/python3.12/site-packages/airflow/cli/commands/task_command.py", line 483, in task_run
    task_return_code = _run_task_by_selected_method(args, _dag, ti)
                       ^^^^^^^^^^^^^^^^^^^^^^^^^^^^^^^^^^^^^^^^^^^^
  File "/home/airflow/.local/lib/python3.12/site-packages/airflow/cli/commands/task_command.py", line 256, in _run_task_by_selected_method
    return _run_raw_task(args, ti)
           ^^^^^^^^^^^^^^^^^^^^^^^
  File "/home/airflow/.local/lib/python3.12/site-packages/airflow/cli/commands/task_command.py", line 341, in _run_raw_task
    return ti._run_raw_task(
           ^^^^^^^^^^^^^^^^^
  File "/home/airflow/.local/lib/python3.12/site-packages/airflow/utils/session.py", line 97, in wrapper
    return func(*args, session=session, **kwargs)
           ^^^^^^^^^^^^^^^^^^^^^^^^^^^^^^^^^^^^^^
  File "/home/airflow/.local/lib/python3.12/site-packages/airflow/models/taskinstance.py", line 3006, in _run_raw_task
    return _run_raw_task(
           ^^^^^^^^^^^^^^
  File "/home/airflow/.local/lib/python3.12/site-packages/airflow/models/taskinstance.py", line 274, in _run_raw_task
    TaskInstance._execute_task_with_callbacks(
  File "/home/airflow/.local/lib/python3.12/site-packages/airflow/models/taskinstance.py", line 3161, in _execute_task_with_callbacks
    result = self._execute_task(context, task_orig)
             ^^^^^^^^^^^^^^^^^^^^^^^^^^^^^^^^^^^^^^
  File "/home/airflow/.local/lib/python3.12/site-packages/airflow/models/taskinstance.py", line 3185, in _execute_task
    return _execute_task(self, context, task_orig)
           ^^^^^^^^^^^^^^^^^^^^^^^^^^^^^^^^^^^^^^^
  File "/home/airflow/.local/lib/python3.12/site-packages/airflow/models/taskinstance.py", line 768, in _execute_task
    result = _execute_callable(context=context, **execute_callable_kwargs)
             ^^^^^^^^^^^^^^^^^^^^^^^^^^^^^^^^^^^^^^^^^^^^^^^^^^^^^^^^^^^^^
  File "/home/airflow/.local/lib/python3.12/site-packages/airflow/models/taskinstance.py", line 734, in _execute_callable
    return ExecutionCallableRunner(
           ^^^^^^^^^^^^^^^^^^^^^^^^
  File "/home/airflow/.local/lib/python3.12/site-packages/airflow/utils/operator_helpers.py", line 252, in run
    return self.func(*args, **kwargs)
           ^^^^^^^^^^^^^^^^^^^^^^^^^^
  File "/home/airflow/.local/lib/python3.12/site-packages/airflow/models/baseoperator.py", line 424, in wrapper
    return func(self, *args, **kwargs)
           ^^^^^^^^^^^^^^^^^^^^^^^^^^^
  File "/home/airflow/.local/lib/python3.12/site-packages/airflow/operators/python.py", line 238, in execute
    return_value = self.execute_callable()
                   ^^^^^^^^^^^^^^^^^^^^^^^
  File "/home/airflow/.local/lib/python3.12/site-packages/airflow/operators/python.py", line 256, in execute_callable
    return runner.run(*self.op_args, **self.op_kwargs)
           ^^^^^^^^^^^^^^^^^^^^^^^^^^^^^^^^^^^^^^^^^^^
  File "/home/airflow/.local/lib/python3.12/site-packages/airflow/utils/operator_helpers.py", line 252, in run
    return self.func(*args, **kwargs)
           ^^^^^^^^^^^^^^^^^^^^^^^^^^
  File "/opt/airflow/dags/sevdesk_to_hubspot.py", line 106, in create_contact_in_hubspot
    raise ValueError(f"Failed to create contact in HubSpot. Status Code: {create_response.status_code}")
ValueError: Failed to create contact in HubSpot. Status Code: 409
[2025-03-17T16:39:57.418+0000] {local_task_job_runner.py:266} INFO - Task exited with return code 1
[2025-03-17T16:39:57.426+0000] {taskinstance.py:3901} INFO - 0 downstream tasks scheduled from follow-on schedule check
[2025-03-17T16:39:57.426+0000] {local_task_job_runner.py:245} INFO - ::endgroup::
